Internal Server Error: /signup/
Traceback (most recent call last):
  File "/home/bafghmah/virtualenv/mahd/3.7/lib/python3.7/site-packages/django/utils/datastructures.py", line 76, in __getitem__
    list_ = super().__getitem__(key)
KeyError: 'motherseri'

During handling of the above exception, another exception occurred:

Traceback (most recent call last):
  File "/home/bafghmah/virtualenv/mahd/3.7/lib/python3.7/site-packages/django/core/handlers/exception.py", line 47, in inner
    response = get_response(request)
  File "/home/bafghmah/virtualenv/mahd/3.7/lib/python3.7/site-packages/django/core/handlers/base.py", line 181, in _get_response
    response = wrapped_callback(request, *callback_args, **callback_kwargs)
  File "/home/bafghmah/virtualenv/mahd/3.7/lib/python3.7/site-packages/django/views/decorators/csrf.py", line 54, in wrapped_view
    return view_func(*args, **kwargs)
  File "/home/bafghmah/mahd/web/views.py", line 27, in SignUp
    motherseri = request.POST['motherseri']
  File "/home/bafghmah/virtualenv/mahd/3.7/lib/python3.7/site-packages/django/utils/datastructures.py", line 78, in __getitem__
    raise MultiValueDictKeyError(key)
django.utils.datastructures.MultiValueDictKeyError: 'motherseri'
Internal Server Error: /signup/
Traceback (most recent call last):
  File "/home/bafghmah/virtualenv/mahd/3.7/lib/python3.7/site-packages/django/utils/datastructures.py", line 76, in __getitem__
    list_ = super().__getitem__(key)
KeyError: 'motherseri'

During handling of the above exception, another exception occurred:

Traceback (most recent call last):
  File "/home/bafghmah/virtualenv/mahd/3.7/lib/python3.7/site-packages/django/core/handlers/exception.py", line 47, in inner
    response = get_response(request)
  File "/home/bafghmah/virtualenv/mahd/3.7/lib/python3.7/site-packages/django/core/handlers/base.py", line 181, in _get_response
    response = wrapped_callback(request, *callback_args, **callback_kwargs)
  File "/home/bafghmah/virtualenv/mahd/3.7/lib/python3.7/site-packages/django/views/decorators/csrf.py", line 54, in wrapped_view
    return view_func(*args, **kwargs)
  File "/home/bafghmah/mahd/web/views.py", line 27, in SignUp
    motherseri = request.POST['motherseri']
  File "/home/bafghmah/virtualenv/mahd/3.7/lib/python3.7/site-packages/django/utils/datastructures.py", line 78, in __getitem__
    raise MultiValueDictKeyError(key)
django.utils.datastructures.MultiValueDictKeyError: 'motherseri'
Internal Server Error: /signup/
Traceback (most recent call last):
  File "/home/bafghmah/virtualenv/mahd/3.7/lib/python3.7/site-packages/django/utils/datastructures.py", line 76, in __getitem__
    list_ = super().__getitem__(key)
KeyError: 'motherseri'

During handling of the above exception, another exception occurred:

Traceback (most recent call last):
  File "/home/bafghmah/virtualenv/mahd/3.7/lib/python3.7/site-packages/django/core/handlers/exception.py", line 47, in inner
    response = get_response(request)
  File "/home/bafghmah/virtualenv/mahd/3.7/lib/python3.7/site-packages/django/core/handlers/base.py", line 181, in _get_response
    response = wrapped_callback(request, *callback_args, **callback_kwargs)
  File "/home/bafghmah/virtualenv/mahd/3.7/lib/python3.7/site-packages/django/views/decorators/csrf.py", line 54, in wrapped_view
    return view_func(*args, **kwargs)
  File "/home/bafghmah/mahd/web/views.py", line 27, in SignUp
    motherseri = request.POST['motherseri']
  File "/home/bafghmah/virtualenv/mahd/3.7/lib/python3.7/site-packages/django/utils/datastructures.py", line 78, in __getitem__
    raise MultiValueDictKeyError(key)
django.utils.datastructures.MultiValueDictKeyError: 'motherseri'
Internal Server Error: /signup/
Traceback (most recent call last):
  File "/home/bafghmah/virtualenv/mahd/3.7/lib/python3.7/site-packages/django/utils/datastructures.py", line 76, in __getitem__
    list_ = super().__getitem__(key)
KeyError: 'motherseri'

During handling of the above exception, another exception occurred:

Traceback (most recent call last):
  File "/home/bafghmah/virtualenv/mahd/3.7/lib/python3.7/site-packages/django/core/handlers/exception.py", line 47, in inner
    response = get_response(request)
  File "/home/bafghmah/virtualenv/mahd/3.7/lib/python3.7/site-packages/django/core/handlers/base.py", line 181, in _get_response
    response = wrapped_callback(request, *callback_args, **callback_kwargs)
  File "/home/bafghmah/virtualenv/mahd/3.7/lib/python3.7/site-packages/django/views/decorators/csrf.py", line 54, in wrapped_view
    return view_func(*args, **kwargs)
  File "/home/bafghmah/mahd/web/views.py", line 27, in SignUp
    motherseri = request.POST['motherseri']
  File "/home/bafghmah/virtualenv/mahd/3.7/lib/python3.7/site-packages/django/utils/datastructures.py", line 78, in __getitem__
    raise MultiValueDictKeyError(key)
django.utils.datastructures.MultiValueDictKeyError: 'motherseri'
Internal Server Error: /signup/
Traceback (most recent call last):
  File "/home/bafghmah/virtualenv/mahd/3.7/lib/python3.7/site-packages/django/core/handlers/exception.py", line 47, in inner
    response = get_response(request)
  File "/home/bafghmah/virtualenv/mahd/3.7/lib/python3.7/site-packages/django/core/handlers/base.py", line 181, in _get_response
    response = wrapped_callback(request, *callback_args, **callback_kwargs)
  File "/home/bafghmah/virtualenv/mahd/3.7/lib/python3.7/site-packages/django/views/decorators/csrf.py", line 54, in wrapped_view
    return view_func(*args, **kwargs)
  File "/home/bafghmah/mahd/web/views.py", line 80, in SignUp
    bimeh=bimeh, shahid=shahid, farhangi=farhangi, children=children, child=child)
  File "/home/bafghmah/virtualenv/mahd/3.7/lib/python3.7/site-packages/django/db/models/manager.py", line 85, in manager_method
    return getattr(self.get_queryset(), name)(*args, **kwargs)
  File "/home/bafghmah/virtualenv/mahd/3.7/lib/python3.7/site-packages/django/db/models/query.py", line 451, in create
    obj = self.model(**kwargs)
  File "/home/bafghmah/virtualenv/mahd/3.7/lib/python3.7/site-packages/django/db/models/base.py", line 503, in __init__
    raise TypeError("%s() got an unexpected keyword argument '%s'" % (cls.__name__, kwarg))
TypeError: Userprofile() got an unexpected keyword argument 'Chid'
Internal Server Error: /signup/
Traceback (most recent call last):
  File "/home/bafghmah/virtualenv/mahd/3.7/lib/python3.7/site-packages/django/core/handlers/exception.py", line 47, in inner
    response = get_response(request)
  File "/home/bafghmah/virtualenv/mahd/3.7/lib/python3.7/site-packages/django/core/handlers/base.py", line 181, in _get_response
    response = wrapped_callback(request, *callback_args, **callback_kwargs)
  File "/home/bafghmah/virtualenv/mahd/3.7/lib/python3.7/site-packages/django/views/decorators/csrf.py", line 54, in wrapped_view
    return view_func(*args, **kwargs)
  File "/home/bafghmah/mahd/web/views.py", line 80, in SignUp
    bimeh=bimeh, shahid=shahid, farhangi=farhangi, children=children, child=child)
  File "/home/bafghmah/virtualenv/mahd/3.7/lib/python3.7/site-packages/django/db/models/manager.py", line 85, in manager_method
    return getattr(self.get_queryset(), name)(*args, **kwargs)
  File "/home/bafghmah/virtualenv/mahd/3.7/lib/python3.7/site-packages/django/db/models/query.py", line 451, in create
    obj = self.model(**kwargs)
  File "/home/bafghmah/virtualenv/mahd/3.7/lib/python3.7/site-packages/django/db/models/base.py", line 503, in __init__
    raise TypeError("%s() got an unexpected keyword argument '%s'" % (cls.__name__, kwarg))
TypeError: Userprofile() got an unexpected keyword argument 'father_phon'
Internal Server Error: /signup/
Traceback (most recent call last):
  File "/home/bafghmah/virtualenv/mahd/3.7/lib/python3.7/site-packages/django/core/handlers/exception.py", line 47, in inner
    response = get_response(request)
  File "/home/bafghmah/virtualenv/mahd/3.7/lib/python3.7/site-packages/django/core/handlers/base.py", line 181, in _get_response
    response = wrapped_callback(request, *callback_args, **callback_kwargs)
  File "/home/bafghmah/virtualenv/mahd/3.7/lib/python3.7/site-packages/django/views/decorators/csrf.py", line 54, in wrapped_view
    return view_func(*args, **kwargs)
  File "/home/bafghmah/mahd/web/views.py", line 80, in SignUp
    bimeh=bimeh, shahid=shahid, farhangi=farhangi, children=children, child=child)
  File "/home/bafghmah/virtualenv/mahd/3.7/lib/python3.7/site-packages/django/db/models/manager.py", line 85, in manager_method
    return getattr(self.get_queryset(), name)(*args, **kwargs)
  File "/home/bafghmah/virtualenv/mahd/3.7/lib/python3.7/site-packages/django/db/models/query.py", line 451, in create
    obj = self.model(**kwargs)
  File "/home/bafghmah/virtualenv/mahd/3.7/lib/python3.7/site-packages/django/db/models/base.py", line 503, in __init__
    raise TypeError("%s() got an unexpected keyword argument '%s'" % (cls.__name__, kwarg))
TypeError: Userprofile() got an unexpected keyword argument 'hand'
Internal Server Error: /signup/
Traceback (most recent call last):
  File "/home/bafghmah/virtualenv/mahd/3.7/lib/python3.7/site-packages/django/core/handlers/exception.py", line 47, in inner
    response = get_response(request)
  File "/home/bafghmah/virtualenv/mahd/3.7/lib/python3.7/site-packages/django/core/handlers/base.py", line 167, in _get_response
    callback, callback_args, callback_kwargs = self.resolve_request(request)
  File "/home/bafghmah/virtualenv/mahd/3.7/lib/python3.7/site-packages/django/core/handlers/base.py", line 290, in resolve_request
    resolver_match = resolver.resolve(request.path_info)
  File "/home/bafghmah/virtualenv/mahd/3.7/lib/python3.7/site-packages/django/urls/resolvers.py", line 556, in resolve
    for pattern in self.url_patterns:
  File "/home/bafghmah/virtualenv/mahd/3.7/lib/python3.7/site-packages/django/utils/functional.py", line 48, in __get__
    res = instance.__dict__[self.name] = self.func(instance)
  File "/home/bafghmah/virtualenv/mahd/3.7/lib/python3.7/site-packages/django/urls/resolvers.py", line 598, in url_patterns
    patterns = getattr(self.urlconf_module, "urlpatterns", self.urlconf_module)
  File "/home/bafghmah/virtualenv/mahd/3.7/lib/python3.7/site-packages/django/utils/functional.py", line 48, in __get__
    res = instance.__dict__[self.name] = self.func(instance)
  File "/home/bafghmah/virtualenv/mahd/3.7/lib/python3.7/site-packages/django/urls/resolvers.py", line 591, in urlconf_module
    return import_module(self.urlconf_name)
  File "/home/bafghmah/virtualenv/mahd/3.7/lib64/python3.7/importlib/__init__.py", line 127, in import_module
    return _bootstrap._gcd_import(name[level:], package, level)
  File "<frozen importlib._bootstrap>", line 1006, in _gcd_import
  File "<frozen importlib._bootstrap>", line 983, in _find_and_load
  File "<frozen importlib._bootstrap>", line 967, in _find_and_load_unlocked
  File "<frozen importlib._bootstrap>", line 677, in _load_unlocked
  File "<frozen importlib._bootstrap_external>", line 728, in exec_module
  File "<frozen importlib._bootstrap>", line 219, in _call_with_frames_removed
  File "/home/bafghmah/mahd/mahd/urls.py", line 23, in <module>
    path('',include('web.urls'))
  File "/home/bafghmah/virtualenv/mahd/3.7/lib/python3.7/site-packages/django/urls/conf.py", line 34, in include
    urlconf_module = import_module(urlconf_module)
  File "/home/bafghmah/virtualenv/mahd/3.7/lib64/python3.7/importlib/__init__.py", line 127, in import_module
    return _bootstrap._gcd_import(name[level:], package, level)
  File "<frozen importlib._bootstrap>", line 1006, in _gcd_import
  File "<frozen importlib._bootstrap>", line 983, in _find_and_load
  File "<frozen importlib._bootstrap>", line 967, in _find_and_load_unlocked
  File "<frozen importlib._bootstrap>", line 677, in _load_unlocked
  File "<frozen importlib._bootstrap_external>", line 728, in exec_module
  File "<frozen importlib._bootstrap>", line 219, in _call_with_frames_removed
  File "/home/bafghmah/mahd/web/urls.py", line 2, in <module>
    from .views import SignUp, Userprofiles,home,UserDetail
  File "/home/bafghmah/mahd/web/views.py", line 79
    telegram_phone=telegram_phone, e_place=eplace, Hand=hand, Talagh=talagh,
                                                  ^
SyntaxError: keyword argument repeated
Internal Server Error: /signup/
Traceback (most recent call last):
  File "/home/bafghmah/virtualenv/mahd/3.7/lib/python3.7/site-packages/django/core/handlers/exception.py", line 47, in inner
    response = get_response(request)
  File "/home/bafghmah/virtualenv/mahd/3.7/lib/python3.7/site-packages/django/core/handlers/base.py", line 167, in _get_response
    callback, callback_args, callback_kwargs = self.resolve_request(request)
  File "/home/bafghmah/virtualenv/mahd/3.7/lib/python3.7/site-packages/django/core/handlers/base.py", line 290, in resolve_request
    resolver_match = resolver.resolve(request.path_info)
  File "/home/bafghmah/virtualenv/mahd/3.7/lib/python3.7/site-packages/django/urls/resolvers.py", line 556, in resolve
    for pattern in self.url_patterns:
  File "/home/bafghmah/virtualenv/mahd/3.7/lib/python3.7/site-packages/django/utils/functional.py", line 48, in __get__
    res = instance.__dict__[self.name] = self.func(instance)
  File "/home/bafghmah/virtualenv/mahd/3.7/lib/python3.7/site-packages/django/urls/resolvers.py", line 598, in url_patterns
    patterns = getattr(self.urlconf_module, "urlpatterns", self.urlconf_module)
  File "/home/bafghmah/virtualenv/mahd/3.7/lib/python3.7/site-packages/django/utils/functional.py", line 48, in __get__
    res = instance.__dict__[self.name] = self.func(instance)
  File "/home/bafghmah/virtualenv/mahd/3.7/lib/python3.7/site-packages/django/urls/resolvers.py", line 591, in urlconf_module
    return import_module(self.urlconf_name)
  File "/home/bafghmah/virtualenv/mahd/3.7/lib64/python3.7/importlib/__init__.py", line 127, in import_module
    return _bootstrap._gcd_import(name[level:], package, level)
  File "<frozen importlib._bootstrap>", line 1006, in _gcd_import
  File "<frozen importlib._bootstrap>", line 983, in _find_and_load
  File "<frozen importlib._bootstrap>", line 967, in _find_and_load_unlocked
  File "<frozen importlib._bootstrap>", line 677, in _load_unlocked
  File "<frozen importlib._bootstrap_external>", line 728, in exec_module
  File "<frozen importlib._bootstrap>", line 219, in _call_with_frames_removed
  File "/home/bafghmah/mahd/mahd/urls.py", line 23, in <module>
    path('',include('web.urls'))
  File "/home/bafghmah/virtualenv/mahd/3.7/lib/python3.7/site-packages/django/urls/conf.py", line 34, in include
    urlconf_module = import_module(urlconf_module)
  File "/home/bafghmah/virtualenv/mahd/3.7/lib64/python3.7/importlib/__init__.py", line 127, in import_module
    return _bootstrap._gcd_import(name[level:], package, level)
  File "<frozen importlib._bootstrap>", line 1006, in _gcd_import
  File "<frozen importlib._bootstrap>", line 983, in _find_and_load
  File "<frozen importlib._bootstrap>", line 967, in _find_and_load_unlocked
  File "<frozen importlib._bootstrap>", line 677, in _load_unlocked
  File "<frozen importlib._bootstrap_external>", line 728, in exec_module
  File "<frozen importlib._bootstrap>", line 219, in _call_with_frames_removed
  File "/home/bafghmah/mahd/web/urls.py", line 2, in <module>
    from .views import SignUp, Userprofiles,home,UserDetail
  File "/home/bafghmah/mahd/web/views.py", line 79
    telegram_phone=telegram_phone, e_place=eplace, Hand=hand, Talagh=talagh,
                                                  ^
SyntaxError: keyword argument repeated
Internal Server Error: /signup/
Traceback (most recent call last):
  File "/home/bafghmah/virtualenv/mahd/3.7/lib/python3.7/site-packages/django/core/handlers/exception.py", line 47, in inner
    response = get_response(request)
  File "/home/bafghmah/virtualenv/mahd/3.7/lib/python3.7/site-packages/django/core/handlers/base.py", line 167, in _get_response
    callback, callback_args, callback_kwargs = self.resolve_request(request)
  File "/home/bafghmah/virtualenv/mahd/3.7/lib/python3.7/site-packages/django/core/handlers/base.py", line 290, in resolve_request
    resolver_match = resolver.resolve(request.path_info)
  File "/home/bafghmah/virtualenv/mahd/3.7/lib/python3.7/site-packages/django/urls/resolvers.py", line 556, in resolve
    for pattern in self.url_patterns:
  File "/home/bafghmah/virtualenv/mahd/3.7/lib/python3.7/site-packages/django/utils/functional.py", line 48, in __get__
    res = instance.__dict__[self.name] = self.func(instance)
  File "/home/bafghmah/virtualenv/mahd/3.7/lib/python3.7/site-packages/django/urls/resolvers.py", line 598, in url_patterns
    patterns = getattr(self.urlconf_module, "urlpatterns", self.urlconf_module)
  File "/home/bafghmah/virtualenv/mahd/3.7/lib/python3.7/site-packages/django/utils/functional.py", line 48, in __get__
    res = instance.__dict__[self.name] = self.func(instance)
  File "/home/bafghmah/virtualenv/mahd/3.7/lib/python3.7/site-packages/django/urls/resolvers.py", line 591, in urlconf_module
    return import_module(self.urlconf_name)
  File "/home/bafghmah/virtualenv/mahd/3.7/lib64/python3.7/importlib/__init__.py", line 127, in import_module
    return _bootstrap._gcd_import(name[level:], package, level)
  File "<frozen importlib._bootstrap>", line 1006, in _gcd_import
  File "<frozen importlib._bootstrap>", line 983, in _find_and_load
  File "<frozen importlib._bootstrap>", line 967, in _find_and_load_unlocked
  File "<frozen importlib._bootstrap>", line 677, in _load_unlocked
  File "<frozen importlib._bootstrap_external>", line 728, in exec_module
  File "<frozen importlib._bootstrap>", line 219, in _call_with_frames_removed
  File "/home/bafghmah/mahd/mahd/urls.py", line 23, in <module>
    path('',include('web.urls'))
  File "/home/bafghmah/virtualenv/mahd/3.7/lib/python3.7/site-packages/django/urls/conf.py", line 34, in include
    urlconf_module = import_module(urlconf_module)
  File "/home/bafghmah/virtualenv/mahd/3.7/lib64/python3.7/importlib/__init__.py", line 127, in import_module
    return _bootstrap._gcd_import(name[level:], package, level)
  File "<frozen importlib._bootstrap>", line 1006, in _gcd_import
  File "<frozen importlib._bootstrap>", line 983, in _find_and_load
  File "<frozen importlib._bootstrap>", line 967, in _find_and_load_unlocked
  File "<frozen importlib._bootstrap>", line 677, in _load_unlocked
  File "<frozen importlib._bootstrap_external>", line 728, in exec_module
  File "<frozen importlib._bootstrap>", line 219, in _call_with_frames_removed
  File "/home/bafghmah/mahd/web/urls.py", line 2, in <module>
    from .views import SignUp, Userprofiles,home,UserDetail
  File "/home/bafghmah/mahd/web/views.py", line 79
    telegram_phone=telegram_phone, e_place=eplace, Hand=hand, Talagh=talagh,
                                                  ^
SyntaxError: keyword argument repeated
Internal Server Error: /signup/
Traceback (most recent call last):
  File "/home/bafghmah/virtualenv/mahd/3.7/lib/python3.7/site-packages/django/core/handlers/exception.py", line 47, in inner
    response = get_response(request)
  File "/home/bafghmah/virtualenv/mahd/3.7/lib/python3.7/site-packages/django/core/handlers/base.py", line 167, in _get_response
    callback, callback_args, callback_kwargs = self.resolve_request(request)
  File "/home/bafghmah/virtualenv/mahd/3.7/lib/python3.7/site-packages/django/core/handlers/base.py", line 290, in resolve_request
    resolver_match = resolver.resolve(request.path_info)
  File "/home/bafghmah/virtualenv/mahd/3.7/lib/python3.7/site-packages/django/urls/resolvers.py", line 556, in resolve
    for pattern in self.url_patterns:
  File "/home/bafghmah/virtualenv/mahd/3.7/lib/python3.7/site-packages/django/utils/functional.py", line 48, in __get__
    res = instance.__dict__[self.name] = self.func(instance)
  File "/home/bafghmah/virtualenv/mahd/3.7/lib/python3.7/site-packages/django/urls/resolvers.py", line 598, in url_patterns
    patterns = getattr(self.urlconf_module, "urlpatterns", self.urlconf_module)
  File "/home/bafghmah/virtualenv/mahd/3.7/lib/python3.7/site-packages/django/utils/functional.py", line 48, in __get__
    res = instance.__dict__[self.name] = self.func(instance)
  File "/home/bafghmah/virtualenv/mahd/3.7/lib/python3.7/site-packages/django/urls/resolvers.py", line 591, in urlconf_module
    return import_module(self.urlconf_name)
  File "/home/bafghmah/virtualenv/mahd/3.7/lib64/python3.7/importlib/__init__.py", line 127, in import_module
    return _bootstrap._gcd_import(name[level:], package, level)
  File "<frozen importlib._bootstrap>", line 1006, in _gcd_import
  File "<frozen importlib._bootstrap>", line 983, in _find_and_load
  File "<frozen importlib._bootstrap>", line 967, in _find_and_load_unlocked
  File "<frozen importlib._bootstrap>", line 677, in _load_unlocked
  File "<frozen importlib._bootstrap_external>", line 728, in exec_module
  File "<frozen importlib._bootstrap>", line 219, in _call_with_frames_removed
  File "/home/bafghmah/mahd/mahd/urls.py", line 23, in <module>
    path('',include('web.urls'))
  File "/home/bafghmah/virtualenv/mahd/3.7/lib/python3.7/site-packages/django/urls/conf.py", line 34, in include
    urlconf_module = import_module(urlconf_module)
  File "/home/bafghmah/virtualenv/mahd/3.7/lib64/python3.7/importlib/__init__.py", line 127, in import_module
    return _bootstrap._gcd_import(name[level:], package, level)
  File "<frozen importlib._bootstrap>", line 1006, in _gcd_import
  File "<frozen importlib._bootstrap>", line 983, in _find_and_load
  File "<frozen importlib._bootstrap>", line 967, in _find_and_load_unlocked
  File "<frozen importlib._bootstrap>", line 677, in _load_unlocked
  File "<frozen importlib._bootstrap_external>", line 728, in exec_module
  File "<frozen importlib._bootstrap>", line 219, in _call_with_frames_removed
  File "/home/bafghmah/mahd/web/urls.py", line 2, in <module>
    from .views import SignUp, Userprofiles,home,UserDetail
  File "/home/bafghmah/mahd/web/views.py", line 79
    telegram_phone=telegram_phone, e_place=eplace, Hand=hand, Talagh=talagh,
                                                  ^
SyntaxError: keyword argument repeated
[UID:1687][52401] Child process with pid: 52682 was killed by signal: 15, core dump: 0
Traceback (most recent call last):
  File "/home/bafghmah/mahd/passenger_wsgi.py", line 1, in <module>
    from mahd.wsgi import application 
  File "/home/bafghmah/mahd/mahd/wsgi.py", line 8, in <module>
    from django.core.wsgi import get_wsgi_application
ModuleNotFoundError: No module named 'django'
[UID:1687][29875] Reached max children process limit: 6, extra: 2, current: 8, busy: 7, please increase LSAPI_CHILDREN.
[UID:1687][29875] Reached max children process limit: 6, extra: 2, current: 8, busy: 8, please increase LSAPI_CHILDREN.
[UID:1687][29875] Reached max children process limit: 6, extra: 2, current: 8, busy: 8, please increase LSAPI_CHILDREN.
[UID:1687][29875] Reached max children process limit: 6, extra: 2, current: 8, busy: 8, please increase LSAPI_CHILDREN.
[UID:1687][29875] Reached max children process limit: 6, extra: 2, current: 8, busy: 8, please increase LSAPI_CHILDREN.
[UID:1687][29875] Reached max children process limit: 6, extra: 2, current: 8, busy: 8, please increase LSAPI_CHILDREN.
[UID:1687][29875] Reached max children process limit: 6, extra: 2, current: 8, busy: 8, please increase LSAPI_CHILDREN.
[UID:1687][29875] Reached max children process limit: 6, extra: 2, current: 8, busy: 8, please increase LSAPI_CHILDREN.
[UID:1687][29875] Reached max children process limit: 6, extra: 2, current: 8, busy: 8, please increase LSAPI_CHILDREN.
[UID:1687][29875] Reached max children process limit: 6, extra: 2, current: 8, busy: 8, please increase LSAPI_CHILDREN.
[UID:1687][29875] Reached max children process limit: 6, extra: 2, current: 8, busy: 8, please increase LSAPI_CHILDREN.
[UID:1687][29875] Reached max children process limit: 6, extra: 2, current: 8, busy: 8, please increase LSAPI_CHILDREN.
[UID:1687][29875] Reached max children process limit: 6, extra: 2, current: 8, busy: 8, please increase LSAPI_CHILDREN.
[UID:1687][29875] Reached max children process limit: 6, extra: 2, current: 8, busy: 8, please increase LSAPI_CHILDREN.
[UID:1687][29875] Reached max children process limit: 6, extra: 2, current: 8, busy: 8, please increase LSAPI_CHILDREN.
[UID:1687][29875] Reached max children process limit: 6, extra: 2, current: 8, busy: 8, please increase LSAPI_CHILDREN.
[UID:1687][29875] Reached max children process limit: 6, extra: 2, current: 8, busy: 8, please increase LSAPI_CHILDREN.
[UID:1687][29875] Reached max children process limit: 6, extra: 2, current: 8, busy: 8, please increase LSAPI_CHILDREN.
[UID:1687][29875] Reached max children process limit: 6, extra: 2, current: 8, busy: 8, please increase LSAPI_CHILDREN.
[UID:1687][29875] Reached max children process limit: 6, extra: 2, current: 8, busy: 8, please increase LSAPI_CHILDREN.
[UID:1687][29875] Reached max children process limit: 6, extra: 2, current: 8, busy: 8, please increase LSAPI_CHILDREN.
[UID:1687][29875] Reached max children process limit: 6, extra: 2, current: 8, busy: 8, please increase LSAPI_CHILDREN.
[UID:1687][29875] Reached max children process limit: 6, extra: 2, current: 8, busy: 8, please increase LSAPI_CHILDREN.
[UID:1687][29875] Reached max children process limit: 6, extra: 2, current: 8, busy: 8, please increase LSAPI_CHILDREN.
[UID:1687][29875] Reached max children process limit: 6, extra: 2, current: 8, busy: 8, please increase LSAPI_CHILDREN.
[UID:1687][29875] Reached max children process limit: 6, extra: 2, current: 8, busy: 8, please increase LSAPI_CHILDREN.
[UID:1687][29875] Reached max children process limit: 6, extra: 2, current: 8, busy: 8, please increase LSAPI_CHILDREN.
[UID:1687][29875] Reached max children process limit: 6, extra: 2, current: 8, busy: 8, please increase LSAPI_CHILDREN.
[UID:1687][29875] Reached max children process limit: 6, extra: 2, current: 8, busy: 8, please increase LSAPI_CHILDREN.
[UID:1687][29875] Reached max children process limit: 6, extra: 2, current: 8, busy: 8, please increase LSAPI_CHILDREN.
[UID:1687][29875] Reached max children process limit: 6, extra: 2, current: 8, busy: 8, please increase LSAPI_CHILDREN.
[UID:1687][29875] Reached max children process limit: 6, extra: 2, current: 8, busy: 8, please increase LSAPI_CHILDREN.
[UID:1687][29875] Reached max children process limit: 6, extra: 2, current: 8, busy: 8, please increase LSAPI_CHILDREN.
[UID:1687][29875] Reached max children process limit: 6, extra: 2, current: 8, busy: 8, please increase LSAPI_CHILDREN.
[UID:1687][29875] Reached max children process limit: 6, extra: 2, current: 8, busy: 8, please increase LSAPI_CHILDREN.
[UID:1687][29875] Reached max children process limit: 6, extra: 2, current: 8, busy: 7, please increase LSAPI_CHILDREN.
[UID:1687][29875] Reached max children process limit: 6, extra: 2, current: 8, busy: 8, please increase LSAPI_CHILDREN.
[UID:1687][29875] Reached max children process limit: 6, extra: 2, current: 8, busy: 7, please increase LSAPI_CHILDREN.
[UID:1687][22707] Child process with pid: 23273 was killed by signal: 15, core dump: 0
[UID:1687][22707] Child process with pid: 23276 was killed by signal: 15, core dump: 0
[UID:1687][22707] Child process with pid: 23274 was killed by signal: 15, core dump: 0
